<?xml version="1.0"?>
<robot name="robot_name">

  <joint name="base_footprint_joint" type="fixed">
    <parent link="base_link" />
    <child link="base_footprint" />
    <origin xyz="0 0 0" rpy="0 0 0" />
  </joint>

  <link name="base_footprint">
    <inertial>
      <mass value="0.1" />
      <origin xyz="0 0 0" rpy="0 0 0" />
      <inertia ixx="1e-5" ixy="0" ixz="0" iyy="1e-5" iyz="0" izz="1e-5" />
    </inertial>
  </link>

  <link name="base_link">
    <visual>
      <origin xyz="3.2 -0.32 0.0" rpy="1.5708 0.0 3.1416" />
      <geometry>
        <mesh filename="package://robot_description/src/meshes/chasis.STL" scale="0.001 0.001 0.001" />
      </geometry>
      <material name="chassis_grey">
        <color rgba="0.5 0.5 0.5 1.0" />
      </material>
    </visual>
    <collision>
      <origin xyz="3.2 -0.32 0.0" rpy="1.5708 0.0 3.1416" />
      <geometry>
        <mesh filename="package://robot_description/src/meshes/chasis.STL" scale="0.001 0.001 0.001" />
      </geometry>
    </collision>
    <inertial>
      <mass value="20.0" />
      <origin xyz="0 0 0.1325" rpy="0 0 0" />
      <inertia ixx="1.0" ixy="0" ixz="0" iyy="1.5" iyz="0" izz="2.0" />
    </inertial>
  </link>

  <link name="drivewhl_l_link">
    <visual>
      <origin xyz="0.1 -0.02 -0.1" rpy="1.5708 0 3.1416" />
      <geometry>
        <mesh filename="package://robot_description/src/meshes/wheel.STL" scale="0.001 0.001 0.001" />
      </geometry>
      <material name="wheel_grey_l">
        <color rgba="0.5 0.5 0.5 1.0" />
      </material>
    </visual>
    <collision>
      <origin xyz="0.1 -0.02 -0.1" rpy="1.5708 0 3.1416" />
      <geometry>
        <mesh filename="package://robot_description/src/meshes/wheel.STL" scale="0.001 0.001 0.001" />
      </geometry>
    </collision>
    <inertial>
      <mass value="2.0" />
      <origin xyz="0 0 0" rpy="0 0 0" />
      <inertia ixx="0.01" ixy="0" ixz="0" iyy="0.01" iyz="0" izz="0.02" />
    </inertial>
  </link>

  <joint name="drivewhl_l_joint" type="continuous">
    <parent link="base_link" />
    <child link="drivewhl_l_link" />
    <origin xyz="0.0 0.23 0.05" rpy="0 0 0" />
    <axis xyz="0 1 0" />
  </joint>

  <link name="drivewhl_r_link">
    <visual>
      <origin xyz="0.1 -0.02 -0.1" rpy="1.5708 0 3.1416" />
      <geometry>
        <mesh filename="package://robot_description/src/meshes/wheel.STL" scale="0.001 0.001 0.001" />
      </geometry>
      <material name="wheel_grey_r">
        <color rgba="0.5 0.5 0.5 1.0" />
      </material>
    </visual>
    <collision>
      <origin xyz="0.1 -0.02 -0.1" rpy="1.5708 0 3.1416" />
      <geometry>
        <mesh filename="package://robot_description/src/meshes/wheel.STL" scale="0.001 0.001 0.001" />
      </geometry>
    </collision>
    <inertial>
      <mass value="2.0" />
      <origin xyz="0 0 0" rpy="0 0 0" />
      <inertia ixx="0.01" ixy="0" ixz="0" iyy="0.01" iyz="0" izz="0.02" />
    </inertial>
  </link>

  <joint name="drivewhl_r_joint" type="continuous">
    <parent link="base_link" />
    <child link="drivewhl_r_link" />
    <origin xyz="0.0 -0.23 0.05" rpy="0 0 0" />
    <axis xyz="0 1 0" />
  </joint>

  <link name="caster_front_right_link">
    <inertial>
      <origin xyz="0 0 0" rpy="0 0 0" />
      <mass value="0.1" />
      <inertia ixx="0.0004" ixy="0" ixz="0" iyy="0.0004" iyz="0" izz="0.0004" />
    </inertial>
    <visual name="">
      <origin xyz="0.0 0.0 0.0" rpy="0.0 0.0 0.0" />
      <geometry>
        <sphere radius="0.06" />
      </geometry>
      <material name="">
        <color rgba="1.0 0.0 0.0 1.0" />
      </material>
    </visual>
    <collision>
      <origin xyz="0.0 0.0 0.0" rpy="0.0 0.0 0.0" />
      <geometry>
        <sphere radius="0.06" />
      </geometry>
    </collision>
  </link>

  <joint name="caster_front_right_joint" type="continuous">
    <parent link="base_link" />
    <child link="caster_front_right_link" />
    <origin xyz="0.3 -0.2 0.0105" rpy="0 0 0" />
    <axis xyz="0 0 1" />
  </joint>

  <link name="caster_front_left_link">
    <inertial>
      <origin xyz="0 0 0" rpy="0 0 0" />
      <mass value="0.1" />
      <inertia ixx="0.0004" ixy="0" ixz="0" iyy="0.0004" iyz="0" izz="0.0004" />
    </inertial>
    <visual name="">
      <origin xyz="0.0 0.0 0.0" rpy="0.0 0.0 0.0" />
      <geometry>
        <sphere radius="0.06" />
      </geometry>
      <material name="">
        <color rgba="1.0 0.0 0.0 1.0" />
      </material>
    </visual>
    <collision>
      <origin xyz="0.0 0.0 0.0" rpy="0.0 0.0 0.0" />
      <geometry>
        <sphere radius="0.06" />
      </geometry>
    </collision>
  </link>

  <joint name="caster_front_left_joint" type="continuous">
    <parent link="base_link" />
    <child link="caster_front_left_link" />
    <origin xyz="0.3 0.2 0.0105" rpy="0 0 0" />
    <axis xyz="0 0 1" />
  </joint>

  <link name="caster_back_right_link">
    <inertial>
      <origin xyz="0 0 0" rpy="0 0 0" />
      <mass value="0.1" />
      <inertia ixx="0.0004" ixy="0" ixz="0" iyy="0.0004" iyz="0" izz="0.0004" />
    </inertial>
    <visual name="">
      <origin xyz="0.0 0.0 0.0" rpy="0.0 0.0 0.0" />
      <geometry>
        <sphere radius="0.06" />
      </geometry>
      <material name="">
        <color rgba="1.0 0.0 0.0 1.0" />
      </material>
    </visual>
    <collision>
      <origin xyz="0.0 0.0 0.0" rpy="0.0 0.0 0.0" />
      <geometry>
        <sphere radius="0.06" />
      </geometry>
    </collision>
  </link>

  <joint name="caster_back_right_joint" type="continuous">
    <parent link="base_link" />
    <child link="caster_back_right_link" />
    <origin xyz="-0.3 -0.2 0.0105" rpy="0 0 0" />
    <axis xyz="0 0 1" />
  </joint>

  <link name="caster_back_left_link">
    <inertial>
      <origin xyz="0 0 0" rpy="0 0 0" />
      <mass value="0.1" />
      <inertia ixx="0.0004" ixy="0" ixz="0" iyy="0.0004" iyz="0" izz="0.0004" />
    </inertial>
    <visual name="">
      <origin xyz="0.0 0.0 0.0" rpy="0.0 0.0 0.0" />
      <geometry>
        <sphere radius="0.06" />
      </geometry>
      <material name="">
        <color rgba="1.0 0.0 0.0 1.0" />
      </material>
    </visual>
    <collision>
      <origin xyz="0.0 0.0 0.0" rpy="0.0 0.0 0.0" />
      <geometry>
        <sphere radius="0.06" />
      </geometry>
    </collision>
  </link>

  <joint name="caster_back_left_joint" type="continuous">
    <parent link="base_link" />
    <child link="caster_back_left_link" />
    <origin xyz="-0.3 0.2 0.0105" rpy="0 0 0" />
    <axis xyz="0 0 1" />
  </joint>

  <link name="zed_camera_link">
    <visual>
      <origin xyz="0 -0.1 0" rpy="0 0 1.5708" />
      <geometry>
        <mesh filename="package://robot_description/src/meshes/zed.STL" scale="0.001 0.001 0.001" />
      </geometry>
      <material name="Gray">
        <color rgba="0.5 0.5 0.5 1.0" />
      </material>
    </visual>
    <collision>
      <origin xyz="0 -0.1 0" rpy="0 0 1.5708" />
      <geometry>
        <mesh filename="package://robot_description/src/meshes/zed.STL" scale="0.001 0.001 0.001" />
      </geometry>
    </collision>
  </link>

  <joint name="zed_camera_joint" type="fixed">
    <parent link="base_link" />
    <child link="zed_camera_link" />
    <origin xyz="0.4 0.03 0.11" rpy="0 0 0" />
  </joint>

  <joint name="zed_camera_optical_joint" type="fixed">
    <parent link="zed_camera_link" />
    <child link="zed_left_optical_frame" />
    <origin xyz="0.0 0.05 0.02" rpy="-1.5708 0 -1.5708" />
  </joint>

  <link name="zed_left_optical_frame">
    <inertial>
      <mass value="0.1" />
      <origin xyz="0 0 0" rpy="0 0 0" />
      <inertia ixx="1e-5" ixy="0" ixz="0" iyy="1e-5" iyz="0" izz="1e-5" />
    </inertial>
    <visual>
      <origin xyz="0 0 0" rpy="0 0 0" />
      <geometry>
        <sphere radius="0.01" />
      </geometry>
      <material name="camera_frame">
        <color rgba="0.0 1.0 0.0 1.0" />
      </material>
    </visual>
    <collision>
      <origin xyz="0 0 0" rpy="0 0 0" />
      <geometry>
        <sphere radius="0.01" />
      </geometry>
    </collision>
  </link>

  <joint name="zed_camera_right_optical_joint" type="fixed">
    <parent link="zed_camera_link" />
    <child link="zed_right_optical_frame" />
    <origin xyz="0 -0.05 0.02" rpy="-1.5708 3.1416 -1.5708" />
  </joint>

  <link name="zed_right_optical_frame">
    <inertial>
      <mass value="0.1" />
      <origin xyz="0 0 0" rpy="0 0 0" />
      <inertia ixx="1e-5" ixy="0" ixz="0" iyy="1e-5" iyz="0" izz="1e-5" />
    </inertial>
    <visual>
      <origin xyz="0 0 0" rpy="0 0 0" />
      <geometry>
        <sphere radius="0.01" />
      </geometry>
      <material name="camera_frame">
        <color rgba="0.0 0.0 1.0 1.0" />
      </material>
    </visual>
    <collision>
      <origin xyz="0 0 0" rpy="0 0 0" />
      <geometry>
        <sphere radius="0.01" />
      </geometry>
    </collision>
  </link>

  <joint name="zed_imu_joint" type="fixed">
    <parent link="zed_camera_link" />
    <child link="zed_imu_link" />
    <origin xyz="0 0 0.02" rpy="0 0 0" />
  </joint>

  <link name="zed_imu_link">
    <inertial>
      <mass value="0.05" />
      <origin xyz="0 0 0" rpy="0 0 0" />
      <inertia ixx="1e-5" ixy="0" ixz="0" iyy="1e-5" iyz="0" izz="1e-5" />
    </inertial>
    <visual>
      <origin xyz="0 0 0" rpy="0 0 0" />
      <geometry>
        <box size="0.02 0.02 0.02" />
      </geometry>
      <material name="imu_frame">
        <color rgba="1.0 1.0 0.0 1.0" />
      </material>
    </visual>
    <collision>
      <origin xyz="0 0 0" rpy="0 0 0" />
      <geometry>
        <box size="0.02 0.02 0.02" />
      </geometry>
    </collision>
  </link>

  <link name="rplidar_c1">
    <inertial>
      <origin xyz="0.0 0.0 0.0" rpy="0.0 0.0 0.0" />
      <mass value="0.4" />
      <inertia ixx="1e-4" ixy="0.0" ixz="0.0" iyy="1e-4" iyz="0.0" izz="2e-4" />
    </inertial>
    <visual name="">
      <origin xyz="0.0 0.0 0.0" rpy="0.0 0.0 0.0" />
      <geometry>
        <cylinder radius="0.05" length="0.02" />
      </geometry>
      <material name="">
        <color rgba="1.0 0.0 0.0 1.0" />
      </material>
    </visual>
    <collision>
      <origin xyz="0.0 0.0 0.0" rpy="0.0 0.0 0.0" />
      <geometry>
        <cylinder radius="0.05" length="0.02" />
      </geometry>
    </collision>
  </link>

  <joint name="rplidar_joint" type="fixed">
    <parent link="base_link" />
    <child link="rplidar_c1" />
    <origin xyz="0.0 0.0 0.4" rpy="0.0 0.0 0.0" />
  </joint>

  <gazebo>
    <plugin filename="gz-sim-joint-controller-system"
      name="gz::sim::systems::JointController">
      <joint_name>drivewhl_l_joint</joint_name>
      <initial_velocity>0.0</initial_velocity>
      <topic>left_motor_angular_vel</topic>
    </plugin>
  </gazebo>
  <gazebo>
    <plugin filename="gz-sim-joint-controller-system"
      name="gz::sim::systems::JointController">
      <joint_name>drivewhl_r_joint</joint_name>
      <initial_velocity>0.0</initial_velocity>
      <topic>right_motor_angular_vel</topic>
    </plugin>
  </gazebo>
  <gazebo>
    <plugin
        filename="ignition-gazebo-odometry-publisher-system"
        name="ignition::gazebo::systems::OdometryPublisher">
        <odom_publish_frequency>30</odom_publish_frequency>
        <odom_topic>ground_truth_odom</odom_topic>
        <odom_frame>odom</odom_frame>
        <robot_base_frame>base_link</robot_base_frame>
    </plugin>
  </gazebo>

  <gazebo>
    <plugin filename="libignition-gazebo-imu-system"
      name="ignition::gazebo::systems::Imu">
    </plugin>
  </gazebo>
  <gazebo reference="zed_imu_link">
    <sensor name="imu_sensor" type="imu">
      <always_on>1</always_on>
      <update_rate>100</update_rate>
      <visualize>true</visualize>
      <topic>/zed/zed_node/imu/data_raw</topic>
      <angular_velocity>
        <noise type="gaussian">
          <mean>0.0</mean>
          <stddev>0.002</stddev>
        </noise>
      </angular_velocity>
      <linear_acceleration>
        <noise type="gaussian">
          <mean>0.0</mean>
          <stddev>0.1</stddev>
        </noise>
      </linear_acceleration>
    </sensor>
  </gazebo>
  <gazebo>
    <plugin
      filename="gz-sim-joint-state-publisher-system"
      name="gz::sim::systems::JointStatePublisher">
      <topic>joint_states</topic>
      <joint_name>drivewhl_l_joint</joint_name>
      <joint_name>drivewhl_r_joint</joint_name>
      <joint_name>caster_front_right_joint</joint_name>
      <joint_name>caster_front_left_joint</joint_name>
      <joint_name>caster_back_right_joint</joint_name>
      <joint_name>caster_back_left_joint</joint_name>
    </plugin>
  </gazebo>

  <gazebo reference="zed_camera_link">
    <plugin
      filename="libignition-gazebo-sensors-system"
      name="ignition::gazebo::systems::Sensors">
      <render_engine>ogre2</render_engine>
    </plugin>

    <sensor name="zed2i_rgb" type="camera">
      <always_on>true</always_on>
      <visualize>true</visualize>
      <update_rate>60</update_rate>

      <camera name="zed2i_rgb">
        <horizontal_fov>1.02974</horizontal_fov>
        <image>
          <width>320</width>
          <height>240</height>
          <format>R8G8B8</format>
        </image>
        <clip>
          <near>0.02</near>
          <far>300</far>
        </clip>
        <noise>
          <type>gaussian</type>
          <mean>0.0</mean>
          <stddev>0.07</stddev>
        </noise>

        <camera_info>
          <width>320</width>
          <height>240</height>
          <K>700 0 960 0 700 540 0 0 1</K>
          <D>0 0 0 0 0</D>
          <distortion_model>plumb_bob</distortion_model>
        </camera_info>
        <camera_info_topic>/zed/zed_node/left/camera_info</camera_info_topic>
        <optical_frame_id>zed_left_optical_frame</optical_frame_id>
      </camera>
      <topic>/zed/zed_node/left/image_rect_color</topic>
    </sensor>

    <sensor name="zed2i_rgb_right" type="camera">
      <always_on>true</always_on>
      <visualize>true</visualize>
      <update_rate>60</update_rate>

      <camera name="zed2i_rgb_right">
        <horizontal_fov>1.02974</horizontal_fov>
        <image>
          <width>320</width>
          <height>240</height>
          <format>R8G8B8</format>
        </image>
        <clip>
          <near>0.02</near>
          <far>300</far>
        </clip>
        <noise>
          <type>gaussian</type>
          <mean>0.0</mean>
          <stddev>0.07</stddev>
        </noise>

        <camera_info>
          <width>320</width>
          <height>240</height>
          <K>700 0 960 0 700 540 0 0 1</K>
          <D>0 0 0 0 0</D>
          <distortion_model>plumb_bob</distortion_model>
        </camera_info>
        <camera_info_topic>/zed/zed_node/right/camera_info</camera_info_topic>
        <optical_frame_id>zed_right_optical_frame</optical_frame_id>
      </camera>
      <topic>/zed/zed_node/right/image_rect_color</topic>
    </sensor>

    <sensor name="zed2i_depth" type="depth">
      <always_on>true</always_on>
      <visualize>true</visualize>
      <update_rate>60</update_rate>
      <depth_camera name="zed2i_depth">
        <horizontal_fov>1.02974</horizontal_fov>
        <clip>
          <near>0.02</near>
          <far>40.0</far>
        </clip>
        <noise>
          <type>gaussian</type>
          <mean>0.0</mean>
          <stddev>0.07</stddev>
        </noise>
        <camera_info>
          <width>320</width>
          <height>240</height>
          <K>700 0 960 0 700 540 0 0 1</K>
          <D>0 0 0 0 0</D>
          <distortion_model>plumb_bob</distortion_model>
        </camera_info>
      </depth_camera>
      <topic>/zed/zed_node/depth/depth_registered</topic>
      <optical_frame_id>zed_left_optical_frame</optical_frame_id>
    </sensor>
  </gazebo>
  <gazebo reference="rplidar_c1">
    <sensor type="gpu_ray" name="lidar_sensor">
      <always_on>1</always_on>
      <visualize>true</visualize>
      <update_rate>20</update_rate>
      <topic>/gz_lidar/scan</topic>
      <lidar>
        <scan>
          <horizontal>
            <samples>720</samples>
            <resolution>1</resolution>
            <min_angle>-3.1415</min_angle>
            <max_angle>3.1415</max_angle>
          </horizontal>
        </scan>
        <range>
          <min>0.8</min>
          <max>60.0</max>
          <resolution>0.01</resolution>
        </range>
        <noise>
          <type>gaussian</type>
          <mean>0.0</mean>
          <stddev>0.01</stddev>
        </noise>
      </lidar>
    </sensor>
  </gazebo>
</robot>